Workbook

Sheet List of Assets
A1: LEGENDA | G1: Category | H1: ID Category | J1: Site | K1: ID Site
B2: Lost/ Missing | G2: Elektronik | H2: I | J2: BSD | K2: 01
B3: Broken | G3: Furniture | H3: II | J3: Deltamas 1 | K3: 02
B4: Sell | G4: Laptop and Komp | H4: III | J4: Deltamas 2 | K4: 03
B5: Odd (See Comment) | G5: Kendaraan | H5: IV
B6: Belum diinput Finance | G6: Machine and Tooling | H6: V
B9: ID | C9: Category | D9: ID Category | E9: Asset ID | F9: Asset Name | G9: Purchase Date | H9: Cost (Finance) | I9: Cost (GA & Supply Chain) | J9: PIC | K9: Department | L9: Site | M9: ID Site | N9: Brand | O9: Model | P9: Serial Number | Q9: Notes | R9: Status | S9: Price
A10: 1 | B10: FA001 | C10: Elektronik | D10: =if(C10=$G$2,$H$2, if(C10=$G$3,$H$3, if(C10=$G$4,$H$4, if(C10=$G$5,$H$5,if(C10=$G$6,$H$6, " "))))) -> I | E10: =CONCATENATE(B10,"/",D10,"/",M10) -> FA001/I/02 | F10: MONITOR DELL P2314H 23 INC | G10: 42005 | H10: 3150000 | L10: Deltamas 1 | M10: =if(L10=$J$2,$K$2,if(L10=$J$3,$K$3,if(L10=$J$4,$K$4," "))) -> 02 | N10: Dell | R10: Lost/ Missing
A11: 2 | B11: FA002 | C11: Laptop and Komp | D11: =if(C11=$G$2,$H$2, if(C11=$G$3,$H$3, if(C11=$G$4,$H$4, if(C11=$G$5,$H$5,if(C11=$G$6,$H$6, " "))))) -> III | E11: =CONCATENATE(B11,"/",D11,"/",M11) -> FA002/III/01 | F11: LAPTOP | G11: 42135 | H11: 6900000 | J11: Diki | K11: Supply Chain | L11: BSD | M11: =if(L11=$J$2,$K$2,if(L11=$J$3,$K$3,if(L11=$J$4,$K$4," "))) -> 01 | R11: Lost/ Missing
A12: 3 | B12: FA003 | C12: Elektronik | D12: =if(C12=$G$2,$H$2, if(C12=$G$3,$H$3, if(C12=$G$4,$H$4, if(C12=$G$5,$H$5,if(C12=$G$6,$H$6, " "))))) -> I | E12: =CONCATENATE(B12,"/",D12,"/",M12) -> FA003/I/01 | F12: HARDISK SEAGATE SRD0NF1 | G12: 42135 | H12: 580000 | J12: Adi Kusumah | K12: Engineering | L12: BSD | M12: =if(L12=$J$2,$K$2,if(L12=$J$3,$K$3,if(L12=$J$4,$K$4," "))) -> 01 | R12: Active
A13: 4 | B13: FA004 | C13: Furniture | D13: =if(C13=$G$2,$H$2, if(C13=$G$3,$H$3, if(C13=$G$4,$H$4, if(C13=$G$5,$H$5,if(C13=$G$6,$H$6, " "))))) -> II | E13: =CONCATENATE(B13,"/",D13,"/",M13) -> FA004/II/01 | F13: BANGKU | G13: 42249 | H13: 2500000 | L13: BSD | M13: =if(L13=$J$2,$K$2,if(L13=$J$3,$K$3,if(L13=$J$4,$K$4," "))) -> 01 | R13: Lost/ Missing
A14: 5 | B14: FA005 | C14: Furniture | D14: =if(C14=$G$2,$H$2, if(C14=$G$3,$H$3, if(C14=$G$4,$H$4, if(C14=$G$5,$H$5,if(C14=$G$6,$H$6, " "))))) -> II | E14: =CONCATENATE(B14,"/",D14,"/",M14) -> FA005/II/01 | F14: RAK | G14: 42252 | H14: 1787190 | L14: BSD | M14: =if(L14=$J$2,$K$2,if(L14=$J$3,$K$3,if(L14=$J$4,$K$4," "))) -> 01 | R14: Broken
A15: 6 | B15: FA006 | C15: Furniture | D15: =if(C15=$G$2,$H$2, if(C15=$G$3,$H$3, if(C15=$G$4,$H$4, if(C15=$G$5,$H$5,if(C15=$G$6,$H$6, " "))))) -> II | E15: =CONCATENATE(B15,"/",D15,"/",M15) -> FA006/II/01 | F15: MEJA PRINTER KOTAK | G15: 42254 | H15: 3034500 | J15: Herfian | K15: Engineering | L15: BSD | M15: =if(L15=$J$2,$K$2,if(L15=$J$3,$K$3,if(L15=$J$4,$K$4," "))) -> 01 | R15: Active
A16: 7 | B16: FA007 | C16: Furniture | D16: =if(C16=$G$2,$H$2, if(C16=$G$3,$H$3, if(C16=$G$4,$H$4, if(C16=$G$5,$H$5,if(C16=$G$6,$H$6, " "))))) -> II | E16: =CONCATENATE(B16,"/",D16,"/",M16) -> FA007/II/01 | F16: LEMARI | G16: 42278 | H16: 570000 | L16: BSD | M16: =if(L16=$J$2,$K$2,if(L16=$J$3,$K$3,if(L16=$J$4,$K$4," "))) -> 01 | R16: Broken
A17: 8 | B17: FA008 | C17: Furniture | D17: =if(C17=$G$2,$H$2, if(C17=$G$3,$H$3, if(C17=$G$4,$H$4, if(C17=$G$5,$H$5,if(C17=$G$6,$H$6, " "))))) -> II | E17: =CONCATENATE(B17,"/",D17,"/",M17) -> FA008/II/01 | F17: KIPAS | G17: 42279 | H17: 220000 | L17: BSD | M17: =if(L17=$J$2,$K$2,if(L17=$J$3,$K$3,if(L17=$J$4,$K$4," "))) -> 01 | R17: Broken
A18: 9 | B18: FA009 | C18: Elektronik | D18: =if(C18=$G$2,$H$2, if(C18=$G$3,$H$3, if(C18=$G$4,$H$4, if(C18=$G$5,$H$5,if(C18=$G$6,$H$6, " "))))) -> I | E18: =CONCATENATE(B18,"/",D18,"/",M18) -> FA009/I/01 | F18: HP SAMSUNG GALAXY | G18: 42338 | H18: 2950000 | L18: BSD | M18: =if(L18=$J$2,$K$2,if(L18=$J$3,$K$3,if(L18=$J$4,$K$4," "))) -> 01 | N18: Samsung | R18: Lost/ Missing
A19: 10 | B19: FA010 | C19: Elektronik | D19: =if(C19=$G$2,$H$2, if(C19=$G$3,$H$3, if(C19=$G$4,$H$4, if(C19=$G$5,$H$5,if(C19=$G$6,$H$6, " "))))) -> I | E19: =CONCATENATE(B19,"/",D19,"/",M19) -> FA010/I/01 | F19: TV | G19: 42403 | H19: 300000 | L19: BSD | M19: =if(L19=$J$2,$K$2,if(L19=$J$3,$K$3,if(L19=$J$4,$K$4," "))) -> 01 | R19: Lost/ Missing
A20: 11 | B20: FA011 | C20: Laptop and Komp | D20: =if(C20=$G$2,$H$2, if(C20=$G$3,$H$3, if(C20=$G$4,$H$4, if(C20=$G$5,$H$5,if(C20=$G$6,$H$6, " "))))) -> III | E20: =CONCATENATE(B20,"/",D20,"/",M20) -> FA011/III/01 | F20: LAPTOP HP I3 | G20: 42675 | H20: 6540000 | K20: Engineering | L20: BSD | M20: =if(L20=$J$2,$K$2,if(L20=$J$3,$K$3,if(L20=$J$4,$K$4," "))) -> 01 | N20: HP | R20: Active
A21: 12 | B21: FA012 | C21: Elektronik | D21: =if(C21=$G$2,$H$2, if(C21=$G$3,$H$3, if(C21=$G$4,$H$4, if(C21=$G$5,$H$5,if(C21=$G$6,$H$6, " "))))) -> I | E21: =CONCATENATE(B21,"/",D21,"/",M21) -> FA012/I/01 | F21: MESIN ABSEN | G21: 42522 | H21: 1500000 | L21: BSD | M21: =if(L21=$J$2,$K$2,if(L21=$J$3,$K$3,if(L21=$J$4,$K$4," "))) -> 01 | R21: Broken
A22: 13 | B22: FA013 | C22: Elektronik | D22: =if(C22=$G$2,$H$2, if(C22=$G$3,$H$3, if(C22=$G$4,$H$4, if(C22=$G$5,$H$5,if(C22=$G$6,$H$6, " "))))) -> I | E22: =CONCATENATE(B22,"/",D22,"/",M22) -> FA013/I/01 | F22: PRINTER | G22: 42566 | H22: 660000 | L22: BSD | M22: =if(L22=$J$2,$K$2,if(L22=$J$3,$K$3,if(L22=$J$4,$K$4," "))) -> 01 | R22: Lost/ Missing
A23: 14 | B23: FA014 | C23: Furniture | D23: =if(C23=$G$2,$H$2, if(C23=$G$3,$H$3, if(C23=$G$4,$H$4, if(C23=$G$5,$H$5,if(C23=$G$6,$H$6, " "))))) -> II | E23: =CONCATENATE(B23,"/",D23,"/",M23) -> FA014/II/01 | F23: KURSI STAFF | G23: 42466 | H23: 900000 | L23: BSD | M23: =if(L23=$J$2,$K$2,if(L23=$J$3,$K$3,if(L23=$J$4,$K$4," "))) -> 01 | R23: Lost/ Missing
A24: 15 | B24: FA015 | C24: Furniture | D24: =if(C24=$G$2,$H$2, if(C24=$G$3,$H$3, if(C24=$G$4,$H$4, if(C24=$G$5,$H$5,if(C24=$G$6,$H$6, " "))))) -> II | E24: =CONCATENATE(B24,"/",D24,"/",M24) -> FA015/II/01 | F24: HECTOR OFFICE TABLE WALNUT BLACK | G24: 42461 | H24: 750000 | J24: Corneleo | K24: Sales & Marketing | L24: BSD | M24: =if(L24=$J$2,$K$2,if(L24=$J$3,$K$3,if(L24=$J$4,$K$4," "))) -> 01 | R24: Active
A25: 16 | B25: FA016 | C25: Laptop and Komp | D25: =if(C25=$G$2,$H$2, if(C25=$G$3,$H$3, if(C25=$G$4,$H$4, if(C25=$G$5,$H$5,if(C25=$G$6,$H$6, " "))))) -> III | E25: =CONCATENATE(B25,"/",D25,"/",M25) -> FA016/III/01 | F25: LAPTOP ASUS ROG GL553V | G25: 42736 | H25: 21000000 | J25: Adi Kusumah | K25: Engineering | L25: BSD | M25: =if(L25=$J$2,$K$2,if(L25=$J$3,$K$3,if(L25=$J$4,$K$4," "))) -> 01 | N25: Asus | R25: Active
A26: 17 | B26: FA017 | C26: Elektronik | D26: =if(C26=$G$2,$H$2, if(C26=$G$3,$H$3, if(C26=$G$4,$H$4, if(C26=$G$5,$H$5,if(C26=$G$6,$H$6, " "))))) -> I | E26: =CONCATENATE(B26,"/",D26,"/",M26) -> FA017/I/01 | F26: PC. DELL PRECISION TOWER 5810 | G26: 42736 | H26: 37505000 | K26: Engineering | L26: BSD | M26: =if(L26=$J$2,$K$2,if(L26=$J$3,$K$3,if(L26=$J$4,$K$4," "))) -> 01 | N26: Dell | R26: Lost/ Missing
A27: 18 | B27: FA018 | C27: Laptop and Komp | D27: =if(C27=$G$2,$H$2, if(C27=$G$3,$H$3, if(C27=$G$4,$H$4, if(C27=$G$5,$H$5,if(C27=$G$6,$H$6, " "))))) -> III | E27: =CONCATENATE(B27,"/",D27,"/",M27) -> FA018/III/01 | F27: LAPTOP ROG GL552VX | G27: 42979 | H27: 13050000 | K27: Engineering | L27: BSD | M27: =if(L27=$J$2,$K$2,if(L27=$J$3,$K$3,if(L27=$J$4,$K$4," "))) -> 01 | N27: Asus | R27: Active
A28: 19 | B28: FA019 | C28: Machine and Tooling | D28: =if(C28=$G$2,$H$2, if(C28=$G$3,$H$3, if(C28=$G$4,$H$4, if(C28=$G$5,$H$5,if(C28=$G$6,$H$6, " "))))) -> V | E28: =CONCATENATE(B28,"/",D28,"/",M28) -> FA019/V/02 | F28: PRINTER 3D | G28: 42979 | H28: 3275000 | L28: Deltamas 1 | M28: =if(L28=$J$2,$K$2,if(L28=$J$3,$K$3,if(L28=$J$4,$K$4," "))) -> 02
A29: 20 | B29: FA020 | C29: Elektronik | D29: =if(C29=$G$2,$H$2, if(C29=$G$3,$H$3, if(C29=$G$4,$H$4, if(C29=$G$5,$H$5,if(C29=$G$6,$H$6, " "))))) -> I | E29: =CONCATENATE(B29,"/",D29,"/",M29) -> FA020/I/02 | F29: AC POLYTRON | G29: 43049 | H29: 3000000 | L29: Deltamas 1 | M29: =if(L29=$J$2,$K$2,if(L29=$J$3,$K$3,if(L29=$J$4,$K$4," "))) -> 02 | N29: Polytron | R29: Lost/ Missing
A30: 21 | B30: FA021 | C30: Furniture | D30: =if(C30=$G$2,$H$2, if(C30=$G$3,$H$3, if(C30=$G$4,$H$4, if(C30=$G$5,$H$5,if(C30=$G$6,$H$6, " "))))) -> II | E30: =CONCATENATE(B30,"/",D30,"/",M30) -> FA021/II/01 | F30: HECTOR OFFICE TABLE WALNUT BLACK | G30: 43132 | H30: 1400000 | K30: HRGA & Legal | L30: BSD | M30: =if(L30=$J$2,$K$2,if(L30=$J$3,$K$3,if(L30=$J$4,$K$4," "))) -> 01 | R30: Active
A31: 22 | B31: FA022 | C31: Laptop and Komp | D31: =if(C31=$G$2,$H$2, if(C31=$G$3,$H$3, if(C31=$G$4,$H$4, if(C31=$G$5,$H$5,if(C31=$G$6,$H$6, " "))))) -> III | E31: =CONCATENATE(B31,"/",D31,"/",M31) -> FA022/III/01 | F31: LAPTOP | G31: 43132 | H31: 14548800 | J31: Hari TM | K31: Engineering | L31: BSD | M31: =if(L31=$J$2,$K$2,if(L31=$J$3,$K$3,if(L31=$J$4,$K$4," "))) -> 01 | R31: Active
A32: 23 | B32: FA023 | C32: Elektronik | D32: =if(C32=$G$2,$H$2, if(C32=$G$3,$H$3, if(C32=$G$4,$H$4, if(C32=$G$5,$H$5,if(C32=$G$6,$H$6, " "))))) -> I | E32: =CONCATENATE(B32,"/",D32,"/",M32) -> FA023/I/01 | F32: Laptop Dell G5590 | G32: 43160 | H32: 31200000 | J32: Agus RH | K32: Engineering | L32: BSD | M32: =if(L32=$J$2,$K$2,if(L32=$J$3,$K$3,if(L32=$J$4,$K$4," "))) -> 01 | N32: Asus | R32: Active
A33: 24 | B33: FA024 | C33: Laptop and Komp | D33: =if(C33=$G$2,$H$2, if(C33=$G$3,$H$3, if(C33=$G$4,$H$4, if(C33=$G$5,$H$5,if(C33=$G$6,$H$6, " "))))) -> III | E33: =CONCATENATE(B33,"/",D33,"/",M33) -> FA024/III/01 | F33: ACER PREDATOR NITRO | G33: 43160 | H33: 10999000 | L33: BSD | M33: =if(L33=$J$2,$K$2,if(L33=$J$3,$K$3,if(L33=$J$4,$K$4," "))) -> 01 | N33: Acer | R33: Lost/ Missing
A34: 25 | B34: FA025 | C34: Elektronik | D34: =if(C34=$G$2,$H$2, if(C34=$G$3,$H$3, if(C34=$G$4,$H$4, if(C34=$G$5,$H$5,if(C34=$G$6,$H$6, " "))))) -> I | E34: =CONCATENATE(B34,"/",D34,"/",M34) -> FA025/I/02 | F34: AC POLYTRON | G34: 43221 | H34: 3000000 | L34: Deltamas 1 | M34: =if(L34=$J$2,$K$2,if(L34=$J$3,$K$3,if(L34=$J$4,$K$4," "))) -> 02 | N34: Polytron | R34: Lost/ Missing
A35: 26 | B35: FA026 | C35: Laptop and Komp | D35: =if(C35=$G$2,$H$2, if(C35=$G$3,$H$3, if(C35=$G$4,$H$4, if(C35=$G$5,$H$5,if(C35=$G$6,$H$6, " "))))) -> III | E35: =CONCATENATE(B35,"/",D35,"/",M35) -> FA026/III/01 | F35: 3 MONITOR + KEYBOARD 2 + MOUSE 2 + ACC + KABEL VGA + KABEL USG EXT STD | G35: 43221 | H35: 4920000 | J35: Bilkis Ismail | K35: PITD | L35: BSD | M35: =if(L35=$J$2,$K$2,if(L35=$J$3,$K$3,if(L35=$J$4,$K$4," "))) -> 01 | R35: Active
A36: 26 | B36: FA026.1 | C36: Laptop and Komp | D36: =if(C36=$G$2,$H$2, if(C36=$G$3,$H$3, if(C36=$G$4,$H$4, if(C36=$G$5,$H$5,if(C36=$G$6,$H$6, " "))))) -> III | E36: =CONCATENATE(B36,"/",D36,"/",M36) -> FA026.1/III/01 | F36: 3 MONITOR + KEYBOARD 2 + MOUSE 2 + ACC + KABEL VGA + KABEL USG EXT STD | G36: 43221 | H36: 4920000 | J36: Rifky Fauzi | K36: Engineering | L36: BSD | M36: =if(L36=$J$2,$K$2,if(L36=$J$3,$K$3,if(L36=$J$4,$K$4," "))) -> 01 | R36: Active
A37: 26 | B37: FA026.2 | C37: Laptop and Komp | D37: =if(C37=$G$2,$H$2, if(C37=$G$3,$H$3, if(C37=$G$4,$H$4, if(C37=$G$5,$H$5,if(C37=$G$6,$H$6, " "))))) -> III | E37: =CONCATENATE(B37,"/",D37,"/",M37) -> FA026.2/III/01 | F37: 3 MONITOR + KEYBOARD 2 + MOUSE 2 + ACC + KABEL VGA + KABEL USG EXT STD | G37: 43221 | H37: 4920000 | J37: Dimas | K37: HRGA & Legal | L37: BSD | M37: =if(L37=$J$2,$K$2,if(L37=$J$3,$K$3,if(L37=$J$4,$K$4," "))) -> 01 | R37: Active
A38: 27 | B38: FA027 | C38: Elektronik | D38: =if(C38=$G$2,$H$2, if(C38=$G$3,$H$3, if(C38=$G$4,$H$4, if(C38=$G$5,$H$5,if(C38=$G$6,$H$6, " "))))) -> I | E38: =CONCATENATE(B38,"/",D38,"/",M38) -> FA027/I/01 | F38: Camera Sony A6400 | G38: 43256 | H38: 9500032 | J38: Yogie | K38: Business & Digital Development | L38: BSD | M38: =if(L38=$J$2,$K$2,if(L38=$J$3,$K$3,if(L38=$J$4,$K$4," "))) -> 01 | N38: Sony | R38: Active
A39: 28 | B39: FA028 | C39: Laptop and Komp | D39: =if(C39=$G$2,$H$2, if(C39=$G$3,$H$3, if(C39=$G$4,$H$4, if(C39=$G$5,$H$5,if(C39=$G$6,$H$6, " "))))) -> III | E39: =CONCATENATE(B39,"/",D39,"/",M39) -> FA028/III/01 | F39: Lenovo IP1205 | G39: 43287 | H39: 3900000 | J39: Rispandi | K39: HRGA & Legal | L39: BSD | M39: =if(L39=$J$2,$K$2,if(L39=$J$3,$K$3,if(L39=$J$4,$K$4," "))) -> 01 | N39: Lenovo | Q39: Tidak terpakai ada di lemari HRGA | R39: Active
A40: 29 | B40: FA029 | C40: Machine and Tooling | D40: =if(C40=$G$2,$H$2, if(C40=$G$3,$H$3, if(C40=$G$4,$H$4, if(C40=$G$5,$H$5,if(C40=$G$6,$H$6, " "))))) -> V | E40: =CONCATENATE(B40,"/",D40,"/",M40) -> FA029/V/02 | F40: 3D PRINTER | G40: 43314 | H40: 2953007 | L40: Deltamas 1 | M40: =if(L40=$J$2,$K$2,if(L40=$J$3,$K$3,if(L40=$J$4,$K$4," "))) -> 02
A41: 30 | B41: FA030 | C41: Elektronik | D41: =if(C41=$G$2,$H$2, if(C41=$G$3,$H$3, if(C41=$G$4,$H$4, if(C41=$G$5,$H$5,if(C41=$G$6,$H$6, " "))))) -> I | E41: =CONCATENATE(B41,"/",D41,"/",M41) -> FA030/I/01 | F41: HP XIAOMI | G41: 43313 | H41: 1320000 | K41: Engineering | L41: BSD | M41: =if(L41=$J$2,$K$2,if(L41=$J$3,$K$3,if(L41=$J$4,$K$4," "))) -> 01 | N41: Xiaomi | R41: Lost/ Missing
A42: 31 | B42: FA031 | C42: Machine and Tooling | D42: =if(C42=$G$2,$H$2, if(C42=$G$3,$H$3, if(C42=$G$4,$H$4, if(C42=$G$5,$H$5,if(C42=$G$6,$H$6, " "))))) -> V | E42: =CONCATENATE(B42,"/",D42,"/",M42) -> FA031/V/01 | F42: 3D PRINTER ANYCUBIC PHOTON | G42: 43378 | H42: 8190000 | J42: Agus RH | K42: Engineering | L42: BSD | M42: =if(L42=$J$2,$K$2,if(L42=$J$3,$K$3,if(L42=$J$4,$K$4," "))) -> 01 | N42: Anycubic | R42: Active
...

Sheet Tag Asset
B2: FA027/I/01 | D2: FA107/I/01 | F2: FA040.10/II/01 | H2: FA040.11/II/01 | J2: FA040.11/II/01 | P2: FA442/I/01 | R2: FA443/I/01 | T2: FA444/I/02 | V2: FA445/I/02
B3: =image("https://image-charts.com/chart?chs=150x150&cht=qr&choe=UTF-8&chl="&ENCODEURL(B2)) | D3: =image("https://image-charts.com/chart?chs=150x150&cht=qr&choe=UTF-8&chl="&ENCODEURL(D2)) | F3: =image("https://image-charts.com/chart?chs=150x150&cht=qr&choe=UTF-8&chl="&ENCODEURL(F2)) | H3: =image("https://image-charts.com/chart?chs=150x150&cht=qr&choe=UTF-8&chl="&ENCODEURL(H2)) | J3: =image("https://image-charts.com/chart?chs=150x150&cht=qr&choe=UTF-8&chl="&ENCODEURL(J2)) | N3: =image("https://image-charts.com/chart?chs=150x150&cht=qr&choe=UTF-8&chl="&ENCODEURL(N2)) | P3: =image("https://image-charts.com/chart?chs=150x150&cht=qr&choe=UTF-8&chl="&ENCODEURL(P2)) | R3: =image("https://image-charts.com/chart?chs=150x150&cht=qr&choe=UTF-8&chl="&ENCODEURL(R2)) | T3: =image("https://image-charts.com/chart?chs=150x150&cht=qr&choe=UTF-8&chl="&ENCODEURL(T2)) | V3: =image("https://image-charts.com/chart?chs=150x150&cht=qr&choe=UTF-8&chl="&ENCODEURL(V2))
B6: FA040.13/II/01 | D6: FA040.14/II/01 | F6: FA040.15/II/01 | H6: FA044/I/01 | J6: FA050/I/01 | N6: FA446/V/01 | P6: FA447/V/02 | R6: FA448/V/02 | T6: FA448/V/02 | V6: FA449/V/02
B7: =image("https://image-charts.com/chart?chs=150x150&cht=qr&choe=UTF-8&chl="&ENCODEURL(B6)) | D7: =image("https://image-charts.com/chart?chs=150x150&cht=qr&choe=UTF-8&chl="&ENCODEURL(D6)) | F7: =image("https://image-charts.com/chart?chs=150x150&cht=qr&choe=UTF-8&chl="&ENCODEURL(F6)) | H7: =image("https://image-charts.com/chart?chs=150x150&cht=qr&choe=UTF-8&chl="&ENCODEURL(H6)) | J7: =image("https://image-charts.com/chart?chs=150x150&cht=qr&choe=UTF-8&chl="&ENCODEURL(J6)) | N7: =image("https://image-charts.com/chart?chs=150x150&cht=qr&choe=UTF-8&chl="&ENCODEURL(N6)) | P7: =image("https://image-charts.com/chart?chs=150x150&cht=qr&choe=UTF-8&chl="&ENCODEURL(P6)) | R7: =image("https://image-charts.com/chart?chs=150x150&cht=qr&choe=UTF-8&chl="&ENCODEURL(R6)) | T7: =image("https://image-charts.com/chart?chs=150x150&cht=qr&choe=UTF-8&chl="&ENCODEURL(T6)) | V7: =image("https://image-charts.com/chart?chs=150x150&cht=qr&choe=UTF-8&chl="&ENCODEURL(V6))
B10: FA063/I/01 | D10: FA070/III/01 | F10: FA108/I/01 | H10: FA177/II/01 | J10: FA212/II/01 | N10: FA450/V/02 | P10: FA451/V/02 | R10: FA452/V/02 | T10: FA453/V/02 | V10: FA454/V/02
B11: =image("https://image-charts.com/chart?chs=150x150&cht=qr&choe=UTF-8&chl="&ENCODEURL(B10)) | D11: =image("https://image-charts.com/chart?chs=150x150&cht=qr&choe=UTF-8&chl="&ENCODEURL(D10)) | F11: =image("https://image-charts.com/chart?chs=150x150&cht=qr&choe=UTF-8&chl="&ENCODEURL(F10)) | H11: =image("https://image-charts.com/chart?chs=150x150&cht=qr&choe=UTF-8&chl="&ENCODEURL(H10)) | J11: =image("https://image-charts.com/chart?chs=150x150&cht=qr&choe=UTF-8&chl="&ENCODEURL(J10)) | N11: =image("https://image-charts.com/chart?chs=150x150&cht=qr&choe=UTF-8&chl="&ENCODEURL(N10)) | P11: =image("https://image-charts.com/chart?chs=150x150&cht=qr&choe=UTF-8&chl="&ENCODEURL(P10)) | R11: =image("https://image-charts.com/chart?chs=150x150&cht=qr&choe=UTF-8&chl="&ENCODEURL(R10)) | T11: =image("https://image-charts.com/chart?chs=150x150&cht=qr&choe=UTF-8&chl="&ENCODEURL(T10)) | V11: =image("https://image-charts.com/chart?chs=150x150&cht=qr&choe=UTF-8&chl="&ENCODEURL(V10))
B14: FA414/V/01 | D14: FA415/II/01 | F14: FA416/II/01 | H14: FA417/III/01 | J14: FA418/V/02 | N14: FA460/V/02 | P14: FA461/V/02 | R14: FA462/V/02 | T14: FA463/V/02 | V14: FA464/V/02
B15: =image("https://image-charts.com/chart?chs=150x150&cht=qr&choe=UTF-8&chl="&ENCODEURL(B14)) | D15: =image("https://image-charts.com/chart?chs=150x150&cht=qr&choe=UTF-8&chl="&ENCODEURL(D14)) | F15: =image("https://image-charts.com/chart?chs=150x150&cht=qr&choe=UTF-8&chl="&ENCODEURL(F14)) | H15: =image("https://image-charts.com/chart?chs=150x150&cht=qr&choe=UTF-8&chl="&ENCODEURL(H14)) | J15: =image("https://image-charts.com/chart?chs=150x150&cht=qr&choe=UTF-8&chl="&ENCODEURL(J14)) | N15: =image("https://image-charts.com/chart?chs=150x150&cht=qr&choe=UTF-8&chl="&ENCODEURL(N14)) | P15: =image("https://image-charts.com/chart?chs=150x150&cht=qr&choe=UTF-8&chl="&ENCODEURL(P14)) | R15: =image("https://image-charts.com/chart?chs=150x150&cht=qr&choe=UTF-8&chl="&ENCODEURL(R14)) | T15: =image("https://image-charts.com/chart?chs=150x150&cht=qr&choe=UTF-8&chl="&ENCODEURL(T14)) | V15: =image("https://image-charts.com/chart?chs=150x150&cht=qr&choe=UTF-8&chl="&ENCODEURL(V14))
B18: FA419/V/02 | D18: FA420/V/02 | F18: FA421/III/01 | H18: FA422/I/01 | J18: FA423/I/01 | N18: FA016/III/01 | P18: FA023/I/01 | R18: FA026/III/01 | T18: FA026.1/III/01 | V18: FA026.2/III/01
B19: =image("https://image-charts.com/chart?chs=150x150&cht=qr&choe=UTF-8&chl="&ENCODEURL(B18)) | D19: =image("https://image-charts.com/chart?chs=150x150&cht=qr&choe=UTF-8&chl="&ENCODEURL(D18)) | F19: =image("https://image-charts.com/chart?chs=150x150&cht=qr&choe=UTF-8&chl="&ENCODEURL(F18)) | H19: =image("https://image-charts.com/chart?chs=150x150&cht=qr&choe=UTF-8&chl="&ENCODEURL(H18)) | J19: =image("https://image-charts.com/chart?chs=150x150&cht=qr&choe=UTF-8&chl="&ENCODEURL(J18)) | N19: =image("https://image-charts.com/chart?chs=150x150&cht=qr&choe=UTF-8&chl="&ENCODEURL(N18)) | P19: =image("https://image-charts.com/chart?chs=150x150&cht=qr&choe=UTF-8&chl="&ENCODEURL(P18)) | R19: =image("https://image-charts.com/chart?chs=150x150&cht=qr&choe=UTF-8&chl="&ENCODEURL(R18)) | T19: =image("https://image-charts.com/chart?chs=150x150&cht=qr&choe=UTF-8&chl="&ENCODEURL(T18)) | V19: =image("https://image-charts.com/chart?chs=150x150&cht=qr&choe=UTF-8&chl="&ENCODEURL(V18))
B22: FA424/V/01 | D22: FA425/III/01 | F22: FA426/I/01 | H22: FA428/II/01 | J22: FA429/II/01 | N22: FA034/III/02 | P22: FA052.1/II/03 | R22: FA252/I/01 | T22: FA094/III/01 | V22: FA465/V/02
B23: =image("https://image-charts.com/chart?chs=150x150&cht=qr&choe=UTF-8&chl="&ENCODEURL(B22)) | D23: =image("https://image-charts.com/chart?chs=150x150&cht=qr&choe=UTF-8&chl="&ENCODEURL(D22)) | F23: =image("https://image-charts.com/chart?chs=150x150&cht=qr&choe=UTF-8&chl="&ENCODEURL(F22)) | H23: =image("https://image-charts.com/chart?chs=150x150&cht=qr&choe=UTF-8&chl="&ENCODEURL(H22)) | J23: =image("https://image-charts.com/chart?chs=150x150&cht=qr&choe=UTF-8&chl="&ENCODEURL(J22)) | N23: =image("https://image-charts.com/chart?chs=150x150&cht=qr&choe=UTF-8&chl="&ENCODEURL(N22)) | P23: =image("https://image-charts.com/chart?chs=150x150&cht=qr&choe=UTF-8&chl="&ENCODEURL(P22)) | R23: =image("https://image-charts.com/chart?chs=150x150&cht=qr&choe=UTF-8&chl="&ENCODEURL(R22)) | T23: =image("https://image-charts.com/chart?chs=150x150&cht=qr&choe=UTF-8&chl="&ENCODEURL(T22)) | V23: =image("https://image-charts.com/chart?chs=150x150&cht=qr&choe=UTF-8&chl="&ENCODEURL(V22))
B26: FA430/II/01 | D26: FA437/III/01 | F26: FA438/III/03 | H26: FA439/III/03 | J26: FA440/I/02 | N26: FA466/V/01 | P26: FA467/V/02 | R26: FA468/V/02 | T26: FA469/V/02 | V26: FA470/V/02
B27: =image("https://image-charts.com/chart?chs=150x150&cht=qr&choe=UTF-8&chl="&ENCODEURL(B26)) | D27: =image("https://image-charts.com/chart?chs=150x150&cht=qr&choe=UTF-8&chl="&ENCODEURL(D26)) | F27: =image("https://image-charts.com/chart?chs=150x150&cht=qr&choe=UTF-8&chl="&ENCODEURL(F26)) | H27: =image("https://image-charts.com/chart?chs=150x150&cht=qr&choe=UTF-8&chl="&ENCODEURL(H26)) | J27: =image("https://image-charts.com/chart?chs=150x150&cht=qr&choe=UTF-8&chl="&ENCODEURL(J26)) | N27: =image("https://image-charts.com/chart?chs=150x150&cht=qr&choe=UTF-8&chl="&ENCODEURL(N26)) | P27: =image("https://image-charts.com/chart?chs=150x150&cht=qr&choe=UTF-8&chl="&ENCODEURL(P26)) | R27: =image("https://image-charts.com/chart?chs=150x150&cht=qr&choe=UTF-8&chl="&ENCODEURL(R26)) | T27: =image("https://image-charts.com/chart?chs=150x150&cht=qr&choe=UTF-8&chl="&ENCODEURL(T26)) | V27: =image("https://image-charts.com/chart?chs=150x150&cht=qr&choe=UTF-8&chl="&ENCODEURL(V26))
N30: FA471/V/02 | P30: FA472/V/02 | R30: FA473/V/02 | T30: FA474/V/02 | V30: FA475/V/02
B31: =image("https://image-charts.com/chart?chs=150x150&cht=qr&choe=UTF-8&chl="&ENCODEURL(B30)) | D31: =image("https://image-charts.com/chart?chs=150x150&cht=qr&choe=UTF-8&chl="&ENCODEURL(D30)) | F31: =image("https://image-charts.com/chart?chs=150x150&cht=qr&choe=UTF-8&chl="&ENCODEURL(F30)) | H31: =image("https://image-charts.com/chart?chs=150x150&cht=qr&choe=UTF-8&chl="&ENCODEURL(H30)) | J31: =image("https://image-charts.com/chart?chs=150x150&cht=qr&choe=UTF-8&chl="&ENCODEURL(J30)) | N31: =image("https://image-charts.com/chart?chs=150x150&cht=qr&choe=UTF-8&chl="&ENCODEURL(N30)) | P31: =image("https://image-charts.com/chart?chs=150x150&cht=qr&choe=UTF-8&chl="&ENCODEURL(P30)) | R31: =image("https://image-charts.com/chart?chs=150x150&cht=qr&choe=UTF-8&chl="&ENCODEURL(R30)) | T31: =image("https://image-charts.com/chart?chs=150x150&cht=qr&choe=UTF-8&chl="&ENCODEURL(T30)) | V31: =image("https://image-charts.com/chart?chs=150x150&cht=qr&choe=UTF-8&chl="&ENCODEURL(V30))
B36: FA476/V/02 | D36: FA477/V/02 | F36: FA478/V/02 | H36: FA479/V/02 | J36: FA480/V/02 | N36: FA481/V/02 | P36: FA482/V/02 | R36: FA483/V/02 | T36: FA484/V/02 | V36: FA485/V/02
B37: =image("https://image-charts.com/chart?chs=150x150&cht=qr&choe=UTF-8&chl="&ENCODEURL(B36)) | D37: =image("https://image-charts.com/chart?chs=150x150&cht=qr&choe=UTF-8&chl="&ENCODEURL(D36)) | F37: =image("https://image-charts.com/chart?chs=150x150&cht=qr&choe=UTF-8&chl="&ENCODEURL(F36)) | H37: =image("https://image-charts.com/chart?chs=150x150&cht=qr&choe=UTF-8&chl="&ENCODEURL(H36)) | J37: =image("https://image-charts.com/chart?chs=150x150&cht=qr&choe=UTF-8&chl="&ENCODEURL(J36)) | N37: =image("https://image-charts.com/chart?chs=150x150&cht=qr&choe=UTF-8&chl="&ENCODEURL(N36)) | P37: =image("https://image-charts.com/chart?chs=150x150&cht=qr&choe=UTF-8&chl="&ENCODEURL(P36)) | R37: =image("https://image-charts.com/chart?chs=150x150&cht=qr&choe=UTF-8&chl="&ENCODEURL(R36)) | T37: =image("https://image-charts.com/chart?chs=150x150&cht=qr&choe=UTF-8&chl="&ENCODEURL(T36)) | V37: =image("https://image-charts.com/chart?chs=150x150&cht=qr&choe=UTF-8&chl="&ENCODEURL(V36))
B40: FA486/V/02 | D40: FA487/V/02 | F40: FA488/V/02 | H40: FA489/V/02 | J40: FA490/V/02 | N40: FA491/V/02 | P40: FA492/V/02 | R40: FA493/V/02 | T40: FA494/V/02 | V40: FA495/V/02
B41: =image("https://image-charts.com/chart?chs=150x150&cht=qr&choe=UTF-8&chl="&ENCODEURL(B40)) | D41: =image("https://image-charts.com/chart?chs=150x150&cht=qr&choe=UTF-8&chl="&ENCODEURL(D40)) | F41: =image("https://image-charts.com/chart?chs=150x150&cht=qr&choe=UTF-8&chl="&ENCODEURL(F40)) | H41: =image("https://image-charts.com/chart?chs=150x150&cht=qr&choe=UTF-8&chl="&ENCODEURL(H40)) | J41: =image("https://image-charts.com/chart?chs=150x150&cht=qr&choe=UTF-8&chl="&ENCODEURL(J40)) | N41: =image("https://image-charts.com/chart?chs=150x150&cht=qr&choe=UTF-8&chl="&ENCODEURL(N40)) | P41: =image("https://image-charts.com/chart?chs=150x150&cht=qr&choe=UTF-8&chl="&ENCODEURL(P40)) | R41: =image("https://image-charts.com/chart?chs=150x150&cht=qr&choe=UTF-8&chl="&ENCODEURL(R40)) | T41: =image("https://image-charts.com/chart?chs=150x150&cht=qr&choe=UTF-8&chl="&ENCODEURL(T40)) | V41: =image("https://image-charts.com/chart?chs=150x150&cht=qr&choe=UTF-8&chl="&ENCODEURL(V40))
B44: FA496/V/02 | D44: FA497/V/02 | F44: FA498/V/02 | H44: FA499/V/02 | J44: FA500/V/02 | N44: FA501/V/02
B45: =image("https://image-charts.com/chart?chs=150x150&cht=qr&choe=UTF-8&chl="&ENCODEURL(B44)) | D45: =image("https://image-charts.com/chart?chs=150x150&cht=qr&choe=UTF-8&chl="&ENCODEURL(D44)) | F45: =image("https://image-charts.com/chart?chs=150x150&cht=qr&choe=UTF-8&chl="&ENCODEURL(F44)) | H45: =image("https://image-charts.com/chart?chs=150x150&cht=qr&choe=UTF-8&chl="&ENCODEURL(H44)) | J45: =image("https://image-charts.com/chart?chs=150x150&cht=qr&choe=UTF-8&chl="&ENCODEURL(J44)) | N45: =image("https://image-charts.com/chart?chs=150x150&cht=qr&choe=UTF-8&chl="&ENCODEURL(N44)) | P45: =image("https://image-charts.com/chart?chs=150x150&cht=qr&choe=UTF-8&chl="&ENCODEURL(P44)) | R45: =image("https://image-charts.com/chart?chs=150x150&cht=qr&choe=UTF-8&chl="&ENCODEURL(R44)) | T45: =image("https://image-charts.com/chart?chs=150x150&cht=qr&choe=UTF-8&chl="&ENCODEURL(T44)) | V45: =image("https://image-charts.com/chart?chs=150x150&cht=qr&choe=UTF-8&chl="&ENCODEURL(V44))
B49: =image("https://image-charts.com/chart?chs=150x150&cht=qr&choe=UTF-8&chl="&ENCODEURL(B48)) | D49: =image("https://image-charts.com/chart?chs=150x150&cht=qr&choe=UTF-8&chl="&ENCODEURL(D48)) | F49: =image("https://image-charts.com/chart?chs=150x150&cht=qr&choe=UTF-8&chl="&ENCODEURL(F48)) | H49: =image("https://image-charts.com/chart?chs=150x150&cht=qr&choe=UTF-8&chl="&ENCODEURL(H48)) | J49: =image("https://image-charts.com/chart?chs=150x150&cht=qr&choe=UTF-8&chl="&ENCODEURL(J48)) | N49: =image("https://image-charts.com/chart?chs=150x150&cht=qr&choe=UTF-8&chl="&ENCODEURL(N48)) | P49: =image("https://image-charts.com/chart?chs=150x150&cht=qr&choe=UTF-8&chl="&ENCODEURL(P48)) | R49: =image("https://image-charts.com/chart?chs=150x150&cht=qr&choe=UTF-8&chl="&ENCODEURL(R48)) | T49: =image("https://image-charts.com/chart?chs=150x150&cht=qr&choe=UTF-8&chl="&ENCODEURL(T48)) | V49: =image("https://image-charts.com/chart?chs=150x150&cht=qr&choe=UTF-8&chl="&ENCODEURL(V48))
B53: =image("https://image-charts.com/chart?chs=150x150&cht=qr&choe=UTF-8&chl="&ENCODEURL(B52)) | D53: =image("https://image-charts.com/chart?chs=150x150&cht=qr&choe=UTF-8&chl="&ENCODEURL(D52)) | F53: =image("https://image-charts.com/chart?chs=150x150&cht=qr&choe=UTF-8&chl="&ENCODEURL(F52)) | H53: =image("https://image-charts.com/chart?chs=150x150&cht=qr&choe=UTF-8&chl="&ENCODEURL(H52)) | J53: =image("https://image-charts.com/chart?chs=150x150&cht=qr&choe=UTF-8&chl="&ENCODEURL(J52)) | N53: =image("https://image-charts.com/chart?chs=150x150&cht=qr&choe=UTF-8&chl="&ENCODEURL(N52)) | P53: =image("https://image-charts.com/chart?chs=150x150&cht=qr&choe=UTF-8&chl="&ENCODEURL(P52)) | R53: =image("https://image-charts.com/chart?chs=150x150&cht=qr&choe=UTF-8&chl="&ENCODEURL(R52)) | T53: =image("https://image-charts.com/chart?chs=150x150&cht=qr&choe=UTF-8&chl="&ENCODEURL(T52)) | V53: =image("https://image-charts.com/chart?chs=150x150&cht=qr&choe=UTF-8&chl="&ENCODEURL(V52))
B57: =image("https://image-charts.com/chart?chs=150x150&cht=qr&choe=UTF-8&chl="&ENCODEURL(B56)) | D57: =image("https://image-charts.com/chart?chs=150x150&cht=qr&choe=UTF-8&chl="&ENCODEURL(D56)) | F57: =image("https://image-charts.com/chart?chs=150x150&cht=qr&choe=UTF-8&chl="&ENCODEURL(F56)) | H57: =image("https://image-charts.com/chart?chs=150x150&cht=qr&choe=UTF-8&chl="&ENCODEURL(H56)) | J57: =image("https://image-charts.com/chart?chs=150x150&cht=qr&choe=UTF-8&chl="&ENCODEURL(J56)) | N57: =image("https://image-charts.com/chart?chs=150x150&cht=qr&choe=UTF-8&chl="&ENCODEURL(N56)) | P57: =image("https://image-charts.com/chart?chs=150x150&cht=qr&choe=UTF-8&chl="&ENCODEURL(P56)) | R57: =image("https://image-charts.com/chart?chs=150x150&cht=qr&choe=UTF-8&chl="&ENCODEURL(R56)) | T57: =image("https://image-charts.com/chart?chs=150x150&cht=qr&choe=UTF-8&chl="&ENCODEURL(T56)) | V57: =image("https://image-charts.com/chart?chs=150x150&cht=qr&choe=UTF-8&chl="&ENCODEURL(V56))
B61: =image("https://image-charts.com/chart?chs=150x150&cht=qr&choe=UTF-8&chl="&ENCODEURL(B60)) | D61: =image("https://image-charts.com/chart?chs=150x150&cht=qr&choe=UTF-8&chl="&ENCODEURL(D60)) | F61: =image("https://image-charts.com/chart?chs=150x150&cht=qr&choe=UTF-8&chl="&ENCODEURL(F60)) | H61: =image("https://image-charts.com/chart?chs=150x150&cht=qr&choe=UTF-8&chl="&ENCODEURL(H60)) | J61: =image("https://image-charts.com/chart?chs=150x150&cht=qr&choe=UTF-8&chl="&ENCODEURL(J60)) | N61: =image("https://image-charts.com/chart?chs=150x150&cht=qr&choe=UTF-8&chl="&ENCODEURL(N60)) | P61: =image("https://image-charts.com/chart?chs=150x150&cht=qr&choe=UTF-8&chl="&ENCODEURL(P60)) | R61: =image("https://image-charts.com/chart?chs=150x150&cht=qr&choe=UTF-8&chl="&ENCODEURL(R60)) | T61: =image("https://image-charts.com/chart?chs=150x150&cht=qr&choe=UTF-8&chl="&ENCODEURL(T60)) | V61: =image("https://image-charts.com/chart?chs=150x150&cht=qr&choe=UTF-8&chl="&ENCODEURL(V60))
B65: =image("https://image-charts.com/chart?chs=150x150&cht=qr&choe=UTF-8&chl="&ENCODEURL(B64)) | D65: =image("https://image-charts.com/chart?chs=150x150&cht=qr&choe=UTF-8&chl="&ENCODEURL(D64)) | F65: =image("https://image-charts.com/chart?chs=150x150&cht=qr&choe=UTF-8&chl="&ENCODEURL(F64)) | H65: =image("https://image-charts.com/chart?chs=150x150&cht=qr&choe=UTF-8&chl="&ENCODEURL(H64)) | J65: =image("https://image-charts.com/chart?chs=150x150&cht=qr&choe=UTF-8&chl="&ENCODEURL(J64)) | N65: =image("https://image-charts.com/chart?chs=150x150&cht=qr&choe=UTF-8&chl="&ENCODEURL(N64)) | P65: =image("https://image-charts.com/chart?chs=150x150&cht=qr&choe=UTF-8&chl="&ENCODEURL(P64)) | R65: =image("https://image-charts.com/chart?chs=150x150&cht=qr&choe=UTF-8&chl="&ENCODEURL(R64)) | T65: =image("https://image-charts.com/chart?chs=150x150&cht=qr&choe=UTF-8&chl="&ENCODEURL(T64)) | V65: =image("https://image-charts.com/chart?chs=150x150&cht=qr&choe=UTF-8&chl="&ENCODEURL(V64))

Sheet Project Deltamas 2
A1: No | B1: Item | C1: Qty | D1: UOM | E1: Price 1 | F1: Product Information | G1: Price 2 | H1: Product Information | I1: Price 3 | J1: Product Information | K1: Notes | L1: First Purchase | S1: Second Purchase
L2: Actual Qty | M2: Actual Price | N2: Shipping Fee | O2: Sub Total | P2: Total | Q2: Status | R2: Remain Qty | S2: Actual Qty | T2: Actual Price | U2: Shipping Fee | V2: Sub Total | W2: Total | X2: Status
A3: OFFICE
A4: 1 | B4: Meja Kerja Office Lt. 2 | C4: 4 | D4: Pcs | E4: 300000 | F4: https://tk.tokopedia.com/ZSSc5DEfp/ | G4: Rp345.000 | H4: https://tk.tokopedia.com/ZSScaCX99/ | I4: Rp325.000 | J4: https://tk.tokopedia.com/ZSScmrg2n/ | L4: 1 | M4: 300000 | N4: 42000 | O4: =L4*M4+N4 -> 342000 | P4: =sum(O4:O21) -> 1587600 | Q4: Proposed | R4: =C4-L4 -> 3 | W4: =sum(V4:V21) -> 0
A5: 2 | B5: Kursi Kerja Office Lt. 2 | C5: 5 | D5: Pcs | E5: Rp299.000 | F5: https://www.ruparupa.com/p/selma-lyon-kursi-kantor-sandaran-rendah-abu-abu.html?itm_source=search&itm_campaign=direct_search&itm_term=kursi-kantor-%26-10605782&itm_device=desktop&queryId=106cf15159825ae1f370f09b142a6a4d&sid=ETFj5JgBdpC1r0iu7vd0 | G5: Rp299.800 | H5: https://tk.tokopedia.com/ZSScmMRaD/ | I5: 230900 | J5: https://tk.tokopedia.com/ZSScmS1TT/ | L5: 4 | M5: 230900 | N5: 58000 | O5: =L5*M5+N5 -> 981600 | Q5: Proposed | R5: =C5-L5 -> 1
A6: 3 | B6: Utilities service (Toilet dan pantry) | C6: 1 | D6: Lot | O6: =L6*M6+N6 -> 0 | R6: =C6-L6 -> 1
A7: 4 | B7: Internet (Instalasi) | C7: 1 | D7: Lot | E7: Rp980.000 | F7: Indibiz | G7: 10000000 | H7: PT MORATELINDO | J7: PT. SMT | O7: =L7*M7+N7 -> 0 | R7: =C7-L7 -> 1
A8: 5 | B8: TV Ruang Meeting | C8: 1 | D8: Pcs | E8: 2397000 | F8: https://tk.tokopedia.com/ZSAUkDvqt/ | G8: 2339900 | H8: https://tk.tokopedia.com/ZSAUk7TTv/ | I8: 2519000 | J8: https://tk.tokopedia.com/ZSAUknwUY/ | K8: TV Android 40" | O8: =L8*M8+N8 -> 0 | R8: =C8-L8 -> 1
A9: 6 | B9: Renovasi lantai 2 (Partisi Ruang meeting) | C9: 1 | D9: Lot | E9: Rp27.563.800 | F9: Designstudio | G9: Rp47.100.000 | H9: Intan Safety Glass | O9: =L9*M9+N9 -> 0 | R9: =C9-L9 -> 1
A10: 7 | B10: AC Office 1/2 pk | C10: 2 | D10: Unit | L10: 2 | O10: =L10*M10+N10 -> 0 | Q10: Installed | R10: =C10-L10 -> 0
A11: 8 | B11: Instalasi AC | C11: 3 | D11: Lot | E11: - | G11: - | I11: - | L11: 3 | O11: =L11*M11+N11 -> 0 | Q11: Installed | R11: =C11-L11 -> 0
A12: 9 | B12: Roller Blind | C12: 1 | D12: Lot | E12: Rp550.000 | F12: CGG Works | O12: =L12*M12+N12 -> 0 | R12: =C12-L12 -> 1
A13: 10 | B13: Meja Ruang Meeting | C13: 1 | D13: Pcs | E13: 1750000 | F13: https://tk.tokopedia.com/ZSAUByWJR/ | G13: 5099000 | H13: https://www.ruparupa.com/informastore/p/sieben-i-i-i-meja-rapat-2012-iw-putih.html | I13: 4199000 | J13: https://www.ruparupa.com/p/informa-maven-meja-rapat-220-abu-abu-cokelat-oak.html?itm_source=product-recommendation-search-result-rr&itm_campaign=direct-search&itm_term=10591345&itm_device=desktop | O13: =L13*M13+N13 -> 0 | R13: =C13-L13 -> 1
A14: 11 | B14: Kursi Ruang Meeting | C14: 5 | D14: Pcs | E14: Rp299.000 | F14: https://www.ruparupa.com/p/selma-lyon-kursi-kantor-sandaran-rendah-abu-abu.html?itm_source=search&itm_campaign=direct_search&itm_term=kursi-kantor-%26-10605782&itm_device=desktop&queryId=106cf15159825ae1f370f09b142a6a4d&sid=ETFj5JgBdpC1r0iu7vd0 | G14: Rp299.800 | H14: https://tk.tokopedia.com/ZSScmMRaD/ | I14: Rp228.900 | J14: https://tk.tokopedia.com/ZSScmS1TT/ | O14: =L14*M14+N14 -> 0 | R14: =C14-L14 -> 5
A15: 12 | B15: Lemari Arsip | C15: 5 | D15: Pcs | E15: 1375000 | F15: https://tk.tokopedia.com/ZSAUS8MTv/ | G15: 1399000 | H15: https://www.ruparupa.com/p/kiev-lemari-arsip-dengan-pintu-kaca-80x40x180-cm-cokelat.html?itm_source=search&itm_campaign=direct_search&itm_term=lemari-arsip-%26-10450019&itm_device=desktop&queryId=d8a62aa5a3480b2e1405fbfbfde2b9b0&sid=hYfv35gBSC0oiPerAXbg | I15: Rp2.331.900 | J15: https://www.tokopedia.com/informa/informa-lemari-arsip-kantor-metal-4-pintu-high-putih-1729857549483148897?extParam=ivf%3Dfalse%26keyword%3Dlemari+arsip+informa%26search_id%3D2025082604364111B9842E0A271F2ADNOG%26src%3Dsearch%26whid%3D17430154&t_id=1756182822447&t_st=5&t_pp=search_result&t_efo=search_pure_goods_card&t_ef=goods_search&t_sm=&t_spt=search_result | O15: =L15*M15+N15 -> 0 | R15: =C15-L15 -> 5
A16: 13 | B16: Printer | C16: 1 | D16: Unit | E16: 2097600 | F16: https://www.tokopedia.com/metroelektro/jkt-printer-epson-l3210-l-3210-l-3210-l3211-l-3211-l-3211-3-in-1-pengganti-epson-l3110-print-scan-copy-a4-all-in-one-garansi-resmi-1731966599558694489?extParam=ivf%3Dfalse%26keyword%3Dprinter+epson+l3210%26search_id%3D20250827072908D947BF06A885DB0214OJ%26src%3Dsearch | G16: 1976000 | H16: https://www.tokopedia.com/fixprint-indonesia/printer-epson-l3210-l3250-print-scan-copy-multifungsi-wifi-wireless-l3210-no-wifi-xantri-ink-deba9?extParam=ivf%3Dtrue%26keyword%3Dprinter+epson+l3210%26search_id%3D20250827072908D947BF06A885DB0214OJ%26src%3Dsearch%26whid%3D12813586 | I16: 1870550 | J16: https://www.tokopedia.com/ciptakaryashop/epson-l3210-all-in-one-ink-tank-printer-hitam-putih-original-tinta-1-set-garansi-resmi-2-tahun-1729826990812267912?extParam=ivf%3Dfalse%26keyword%3Dprinter+epson+l3210%26search_id%3D20250827072908D947BF06A885DB0214OJ%26src%3Dsearch | O16: =L16*M16+N16 -> 0 | R16: =C16-L16 -> 1
A17: 14 | B17: PC Komputer Admin | C17: 1 | D17: Set | E17: 2469050 | F17: https://tk.tokopedia.com/ZSAadebyn/ | G17: 2411100 | H17: https://tk.tokopedia.com/ZSAaewdp9/ | I17: 2193550 | J17: https://tk.tokopedia.com/ZSAadRMky/ | O17: =L17*M17+N17 -> 0 | R17: =C17-L17 -> 1
A18: 15 | B18: Mesin absensi (attendance) | C18: 1 | D18: Pcs | E18: 1306000 | F18: https://tk.tokopedia.com/ZSA6L5q9J/ | G18: 1083000 | H18: https://tk.tokopedia.com/ZSA6BrEFw/ | I18: Rp1.679.000 | J18: https://www.tokopedia.com/solutionofficial/mesin-absensi-fingerprint-solution-x100-c?extParam=ivf%3Dfalse%26keyword%3Dmeisn+absensi+%26search_id%3D20250826043741577BCC914F9E55011N2C%26src%3Dsearch&t_id=1756182822447&t_st=6&t_pp=search_result&t_efo=search_pure_goods_card&t_ef=goods_search&t_sm=&t_spt=search_result | K18: Ambil dari Delta 1 | O18: =L18*M18+N18 -> 0 | R18: =C18-L18 -> 1
A19: 16 | B19: Tempat sampah Kecil | C19: 6 | D19: Pcs | E19: 14012 | F19: https://tk.tokopedia.com/ZSAadnVkK/ | G19: 19950 | H19: https://tk.tokopedia.com/ZSAaR1TQW/ | I19: 29999 | J19: https://tk.tokopedia.com/ZSApgnuQr/ | M19: 29999 | N19: 0 | O19: =L19*M19+N19 -> 0 | R19: =C19-L19 -> 6
A20: 17 | B20: Tempat sampah Sedang | C20: 2 | D20: Pcs | E20: 117000 | F20: https://tk.tokopedia.com/ZSApbJAQB/ | G20: 95000 | H20: https://tk.tokopedia.com/ZSApqK96f/ | K20: >60 Liter | L20: 2 | M20: 117000 | N20: 30000 | O20: =L20*M20+N20 -> 264000 | Q20: Proposed | R20: =C20-L20 -> 0
A21: 18 | B21: Tempat sampah area | C21: 1 | D21: Pcs | O21: =L21*M21+N21 -> 0 | R21: =C21-L21 -> 1
A22: SURVEILANCE
A23: 1 | B23: Magnetic Door | C23: 6 | D23: Unit | E23: Rp650.000 | F23: https://www.tokopedia.com/buditronik/m-loock-solution-magnetic-door-sliding-door-full-set?extParam=ivf%3Dfalse%26keyword%3Dmagnetic+door%26search_id%3D2025082604491637BC2F75BF1BCF296A71%26src%3Dsearch&t_id=1756183763009&t_st=1&t_pp=search_result&t_efo=search_pure_goods_card&t_ef=goods_search&t_sm=&t_spt=search_result | G23: Rp925.252 | H23: https://www.tokopedia.com/dur-elektronik/solution-magnetic-door-model-em-600?extParam=ivf%3Dfalse%26keyword%3Dmagnetic+door%26search_id%3D2025082604491637BC2F75BF1BCF296A71%26src%3Dsearch&t_id=1756183763009&t_st=2&t_pp=search_result&t_efo=search_pure_goods_card&t_ef=goods_search&t_sm=&t_spt=search_result | I23: Rp880.000 | J23: https://www.tokopedia.com/data-online-system/solution-magnetic-door?extParam=ivf%3Dfalse%26keyword%3Dmagnetic+door%26search_id%3D2025082604491637BC2F75BF1BCF296A71%26src%3Dsearch&t_id=1756183763009&t_st=3&t_pp=search_result&t_efo=search_pure_goods_card&t_ef=goods_search&t_sm=&t_spt=search_result | O23: =L23*M23+N23 -> 0 | P23: =sum(O23:O29) -> 0 | R23: =C23-L23 -> 6 | W23: =sum(V23:V29) -> 0
A24: 2 | B24: Automatic Door Closer | C24: 6 | D24: Unit | E24: Rp81,700 | F24: https://tk.tokopedia.com/ZSAaNML5S/ | G24: Rp85,498 | H24: https://tk.tokopedia.com/ZSAaNjCDk/ | I24: Rp120,650 | J24: https://tk.tokopedia.com/ZSAaNY2us/ | O24: =L24*M24+N24 -> 0 | R24: =C24-L24 -> 6
A25: 3 | B25: Akses Door | C25: 1 | D25: Unit | E25: Rp559.000 | F25: https://tk.tokopedia.com/ZSAfB18Jv/ | G25: Rp2.132.000 | H25: Putra Teknologi Mandiri | O25: =L25*M25+N25 -> 0 | R25: =C25-L25 -> 1
A26: 4 | B26: Instalasi Door Akses | C26: 1 | D26: Unit | E26: Rp550.000 | F26: https://tk.tokopedia.com/ZSAfBBaCj/ | G26: Rp0 | H26: Include Putra Teknologi Mandiri | O26: =L26*M26+N26 -> 0 | R26: =C26-L26 -> 1
A27: 5 | B27: Monitor CCTV | C27: 1 | D27: Pcs | E27: Rp2.397.000 | F27: https://tk.tokopedia.com/ZSAUkDvqt/ | G27: Rp2.339.900 | H27: https://tk.tokopedia.com/ZSAUk7TTv/ | I27: Rp2.519.000 | J27: https://tk.tokopedia.com/ZSAUknwUY/ | K27: TV HDMI 40" | O27: =L27*M27+N27 -> 0 | R27: =C27-L27 -> 1
A28: 6 | B28: CCTV 12 titik | C28: 1 | D28: Lot | E28: Rp10.750.000 | F28: https://tk.tokopedia.com/ZSAfBQaxd/ | G28: Rp39.594.599 | H28: Cendana Teknik | I28: Rp11.523.000 | J28: https://www.tokopedia.com/cctvcom10/paket-cctv-hikvision-5mp-8-channel-8-camera-turbo-hd-kamera-cctv-infrared-1730179095987193151?extParam=ivf%3Dfalse%26keyword%3Dcctv+krisbow%26search_id%3D2025082606201611B9842E0A271F284857%26src%3Dsearch | L28: 1 | O28: =L28*M28+N28 -> 0 | R28: =C28-L28 -> 0
A29: 7 | B29: Instalasi CCTV | C29: 1 | D29: Lot | G29: Rp0 | H29: Include Cendana Teknik | O29: =L29*M29+N29 -> 0 | R29: =C29-L29 -> 1
A30: LISTRIK OFFICE
A31: 1 | B31: Kabel TC 6 | C31: 10 | D31: Pcs | E31: 9975 | F31: https://tk.tokopedia.com/ZSAaLexsA/ | G31: 9025 | H31: https://tk.tokopedia.com/ZSAa8t6f3/ | I31: 8550 | J31: https://tk.tokopedia.com/ZSAa8ga7X/ | O31: =L31*M31+N31 -> 0 | P31: =sum(O31:O40) -> 2500000 | R31: =C31-L31 -> 10 | W31: =sum(V31:V40) -> 0
A32: 2 | B32: Bracket Standing TV | C32: 1 | D32: Pcs | E32: 485000 | F32: https://tk.tokopedia.com/ZSA61PyUP/ | G32: 465000 | H32: https://tk.tokopedia.com/ZSA61PP7k/ | I32: 425625 | J32: https://tk.tokopedia.com/ZSA61kbCf/ | K32: 32 - 55 inch | O32: =L32*M32+N32 -> 0 | R32: =C32-L32 -> 1
A33: 3 | B33: Kabel HDMI 2.0 3 Meter | C33: 2 | D33: Pcs | E33: 68305 | F33: https://tk.tokopedia.com/ZSAa87kx9/ | G33: 33250 | H33: https://tk.tokopedia.com/ZSAa8gfLx/ | I33: 66500 | J33: https://tk.tokopedia.com/ZSAaLLwjx/ | K33: Vention, Ugreen, Bafo | O33: =L33*M33+N33 -> 0 | R33: =C33-L33 -> 2
A34: 4 | B34: Bracket Dinding TV | C34: 1 | D34: Pcs | E34: 37524 | F34: https://tk.tokopedia.com/ZSAaLAgoE/ | G34: 25555 | H34: https://tk.tokopedia.com/ZSAaLBEbE/ | I34: 61655 | J34: https://tk.tokopedia.com/ZSAaLaJfx/ | K34: 42" | O34: =L34*M34+N34 -> 0 | R34: =C34-L34 -> 1
A35: 5 | B35: Locker Besi 12 Pintu | C35: 1 | D35: Pcs | E35: 2199000 | F35: https://www.ruparupa.com/p/informa-kiev-loker-12-pintu-cokelat-muda.html?itm_source=search&itm_campaign=direct_search&itm_term=loker-besi-12-pintu-%26-10507509&itm_device=desktop&queryId=b0164af4e6ca5e2197c284e491c63c8b&sid=ryC4CZkBeHn2cx7nL1Z4 | G35: 1995000 | H35: https://tk.tokopedia.com/ZSAaL2t8T/ | I35: 2283100 | J35: https://tk.tokopedia.com/ZSAaLUSho/ | M35: 1995000 | O35: =L35*M35+N35 -> 0 | Q35: Proposed | R35: =C35-L35 -> 1
A36: 6 | B36: Stekker Arde Broco | C36: 12 | D36: Pcs | E36: 8835 | F36: https://tk.tokopedia.com/ZSAaLF5Yp/ | G36: 10640 | H36: https://tk.tokopedia.com/ZSAaLBW9G/ | I36: 9310 | J36: https://tk.tokopedia.com/ZSAaLT4sM/ | O36: =L36*M36+N36 -> 0 | R36: =C36-L36 -> 12
A37: 7 | B37: Stekker T Broco | C37: 3 | D37: Pcs | E37: 19950 | F37: https://tk.tokopedia.com/ZSAaLGWe2/ | G37: 25441 | H37: https://tk.tokopedia.com/ZSAaL3VFp/ | I37: 19760 | J37: https://tk.tokopedia.com/ZSAaLWPy2/ | O37: =L37*M37+N37 -> 0 | R37: =C37-L37 -> 3
A38: 8 | B38: Colokan 5 Lubang | C38: 12 | D38: Pcs | E38: 61636 | F38: https://tk.tokopedia.com/ZSAaLVDxW/ | G38: 58235 | H38: https://tk.tokopedia.com/ZSAaLs52k/ | I38: 61190 | J38: https://tk.tokopedia.com/ZSAaLcrTe/ | O38: =L38*M38+N38 -> 0 | R38: =C38-L38 -> 12
A39: 9 | B39: Lampu LED Philips | C39: 4 | D39: Pcs | E39: 122857 | F39: https://tk.tokopedia.com/ZSAMc7KB6/ | G39: 109990 | H39: https://tk.tokopedia.com/ZSAM3M9Qs/ | K39: 10 Watt | O39: =L39*M39+N39 -> 0 | R39: =C39-L39 -> 4
A40: 10 | B40: Sertifikasi Instalasi Listrik | C40: 1 | D40: Pc | E40: 2500000 | F40: CV IAM HERE INSPIRATION | L40: 1 | M40: 2500000 | N40: 0 | O40: =L40*M40+N40 -> 2500000 | Q40: On Process | R40: =C40-L40 -> 0
...

Sheet Tools Akinawa
A1: Category | B1: No | C1: Type | D1: Qty | E1: Unit | F1: Kondisi | G1: Tanggal Keluar | H1: Dokumen Surat Keluar
H2: Dokumen di upload pada folder berikut Dokumen Surat Keluar - Tools Akinawa
A3: ARBOR BT 50 | B3: 1 | C3: Arbor Angle Head | D3: 2 | E3: PCS | F3: Belum terpakai
B4: 2 | C4: Arbor L400 Shank 48 | D4: 1 | E4: PCS | F4: Ok
B5: 3 | C5: Arbor L350 Shank 48 | D5: 1 | E5: PCS | F5: Ok
B6: 4 | C6: Arbor L200 Shank 48 | D6: 1 | E6: PCS | F6: Ok
B7: 5 | C7: Arbor Facemill 200 | D7: 1 | E7: PCS | F7: Ok
B8: 6 | C8: Arbor Drill Tapper | D8: 1 | E8: PCS | F8: Belum terpakai
B9: 7 | C9: Arbor L70 Shank 72 | D9: 1 | E9: PCS | F9: Ok
B10: 8 | C10: Arbor Drill Tapper | D10: 1 | E10: PCS | F10: Ok
B11: 9 | C11: Arbor L100 Shank 34 | D11: 1 | E11: PCS | F11: Ok
B12: 10 | C12: Arbor L80 Shank 48 | D12: 1 | E12: PCS | F12: Ok
B13: 11 | C13: Arbor Drill Tapper | D13: 1 | E13: PCS | F13: Ok
B14: 12 | C14: Arbor L100 Shank 35 | D14: 1 | E14: PCS | F14: Ok
B15: 13 | C15: Arbor L100 Shank 44 | D15: 1 | E15: PCS | F15: Ok
... B43: 41 | C43: Arbor ER 40 | D43: 2 | E43: PCS | F43: Ok
A44: ARBOR BT 40 | B44: 1 | C44: Arbor Rusak / Tidak Terpakai dari pertama datang Qty 23 Pcs
C45: Arbor BT 30 / Milling Manual 4 Pcs
B46: 2 | C46: Arbor L 100 Shank 34 | D46: 1 | E46: PCS | F46: OK
B47: 3 | C47: Arbor L100 Shank 50 | D47: 4 | E47: PCS | F47: OK
B48: 4 | C48: Arbor L50 | D48: 5 | E48: PCS | F48: OK
B49: 5 | C49: Arbor Chuck Drill | D49: 2 | E49: PCS | F49: OK
B50: 6 | C50: Arbor L50 Shank 48 | D50: 1 | E50: PCS | F50: OK
B51: 7 | C51: Arbor L130 Shank 48 | D51: 1 | E51: PCS | F51: OK
B52: 8 | C52: Arbor Type C | D52: 1 | E52: PCS | F52: OK
A53: ALAT BANTU | B53: 1 | C53: Ragum Vise Hidrolik | D53: 1 | E53: Pcs | F53: OK
B54: 2 | C54: Rotary Table | D54: 1 | E54: Set | F54: Belum Dipakai
B55: 3 | C55: Ragum manual kotak | D55: 10 | E55: Pcs | F55: Tidak terpakai
B56: 4 | C56: Ragum manual kotak | D56: 1 | E56: Pcs | F56: Ok
B57: 5 | C57: Ragum Bulat | D57: 6 | E57: Pcs | F57: Tidak terpakai
B58: 6 | C58: Dongkrak Hijau | D58: 1 | E58: Pcs | F58: OK
B59: 7 | C59: Kepala Takel / Crane | D59: 1 | E59: Pcs | F59: Tidak terpakai
B60: 8 | C60: Adjuster | D60: 13 | E60: Pcs | F60: OK
B61: 9 | C61: Kepala Boring Head | D61: 4 | E61: Pcs | F61: OK
B62: 10 | C62: Kepala Facemill 80 Apmt | D62: 1 | E62: Pcs | F62: OK
B63: 11 | C63: Kepala Facemill 63 Apmt | D63: 1 | E63: Pcs | F63: OK
B64: 12 | C64: Kepala Facemill 50 Apmt | D64: 1 | E64: Pcs | F64: OK
B65: 13 | C65: Collet ER 40 | D65: 32 | E65: Pcs | F65: OK
... B74: 22 | C74: Chuck Drill Bubut Manual | D74: 1 | E74: Pcs | F74: OK
A75: DRILL | B75: 1 | C75: Drill Ø 49 | D75: 1 | E75: Pcs | F75: Ok (Tidak Terpakai)
...

Sheet Sheet9
C1: PT Imajin Manufaktur Indonesia
A3: Biaya Tambahan Instalasi CCTV
A4: No | B4: Item | C4: Qty | D4: Price | E4: Shipping Fee | F4: Sub Total | G4: Notes | I4: *Harga tidak termasuk ongkir
A5: 1 | B5: Connector BNC | C5: 24 | D5: 15000 | E5: 0 | F5: =C5*D5+E5 -> 360000 | G5: Dibayarkan ke teknisi | I5: No | J5: Item | K5: Volume (L) | L5: Price 1 | M5: Supplier 1 | N5: Price 2 | O5: Supplier 2
A6: 2 | B6: Connector DC | C6: 12 | D6: 10000 | E6: 0 | F6: =C6*D6+E6 -> 120000 | I6: 1 | J6: Polytron | K6: 190 | L6: 3455700 | M6: https://tk.tokopedia.com/ZSUPneQQa/
A7: 3 | B7: Power Supply 20A | C7: 1 | D7: 320000 | E7: 0 | F7: =C7*D7+E7 -> 320000 | I7: 2 | J7: Polytron | K7: 230 | L7: 3673800 | M7: https://tk.tokopedia.com/ZSUPnrGT2/
A8: 4 | B8: Isolasi | C8: 2 | D8: 15000 | E8: 0 | F8: =C8*D8+E8 -> 30000 | I8: 3 | J8: GEA | K8: 222 | L8: 4090100 | M8: https://tk.tokopedia.com/ZSUPnLTne/ | N8: 4015000 | O8: https://tk.tokopedia.com/ZSUPWVoT2/
A9: 5 | B9: Cable Ties | C9: 2 | D9: 25000 | E9: 0 | F9: =C9*D9+E9 -> 50000 | I9: 4 | J9: GEA | K9: 192 | L9: 3625000 | M9: https://tk.tokopedia.com/ZSUPnGATg/ | N9: 3550000 | O9: https://tk.tokopedia.com/ZSUP7jSSp/
A10: 6 | B10: Doradus | C10: 8 | D10: 20000 | E10: 0 | F10: =C10*D10+E10 -> 160000 | I10: 5 | J10: Sanken | K10: 180 | L10: 3424000 | M10: https://tk.tokopedia.com/ZSUPnv8VW/
A11: 7 | B11: Kabel HDMI | C11: 1 | D11: 270000 | E11: 0 | F11: =C11*D11+E11 -> 270000 | I11: 6 | J11: Sanken | K11: 220 | L11: 3789000 | M11: https://tk.tokopedia.com/ZSUPnW3YT/
A12: 8 | B12: Biaya Tarikan Kabel | C12: 170 | D12: 5000 | E12: 0 | F12: =C12*D12+E12 -> 850000 | I12: 7 | J12: RSA | K12: 240 | L12: 3320000 | M12: https://tk.tokopedia.com/ZSUPWtAJU/
A13: 9 | B13: Kabel RG6 | C13: 300 | D13: =798000/300 -> 2660 | E13: 38000 | F13: =C13*D13+E13 -> 836000 | G13: https://tk.tokopedia.com/ZSUUK2r1S/
A14: 10 | B14: Monitor Dahua 22 inch | C14: 1 | D14: 941000 | E14: 28000 | F14: =C14*D14+E14 -> 969000 | G14: https://tk.tokopedia.com/ZSUUKRS77/
A15: 11 | B15: Sewa Tangga | C15: 2 | D15: 150000 | E15: 0 | F15: =(C15*D15)+E15 -> 300000
A16: Grand Total | F16: =SUM(F5:F15) -> 4265000
A18: Catatan | D18: Disetujui Oleh
D19: Shela Oktania | F19: Harmoko

Sheet Maintenance Asset
A1: Access Link Maintenance Report
A2: Maintenance Report
A4: No | B4: Tanggal Maintenance | C4: Nomor Asset | D4: Nama Asset | E4: Identitas Asset | F4: Komponen Perbaikan | G4: Person in Charge | H4: Maintenance Fee
A5: 1 | B5: 45668 | C5: FA322/IV/01 | D5: HONDA VARIO 125 | F5: Pembayaran pajak tahunan | G5: Rispandi
A6: 2 | B6: 45677 | C6: FA323/IV/02 | D6: ALL NEW AVANZA 1.3 E CVT | E6: F 1310 FBM | F6: Pembayaran pajak tahunan | G6: Mahmudin
A7: 3 | B7: 45700 | C7: FA322/IV/01 | D7: HONDA VARIO 125 | F7: Perpanjangan asuransi | G7: Della
A8: 4 | B8: 45755 | C8: FA073/IV/01 | D8: Daihatsu Granmax | E8: F 82526 HS | F8: Perpanjangan izin KIR | G8: Rispandi | H8: 100000
A9: 5 | B9: 45756 | C9: FA247/IV/02 | D9: Truk Isuzu Elf NKR 55 CC E2-1 | E9: F 8298 MC | F9: Pembayaran pajak tahunan | G9: Mahmudin
A10: 6 | B10: 45776 | C10: FA323/IV/02 | D10: ALL NEW AVANZA 1.3 E CVT | E10: F 1310 FBM | F10: Service Rutin Avanza Auto2000 | G10: Mahmudin | H10: 0
A11: 7 | B11: 45802 | C11: FA247/IV/02 | D11: Truk Isuzu Elf NKR 55 CC E2-1 | E11: F 8298 MC | F11: Ganti oli mesin, Filter Solar, Filter Oli | G11: Mahmudin | H11: 576000
A12: 8 | B12: 45832 | C12: FA247/IV/02 | D12: Truk Isuzu Elf NKR 55 CC E2-1 | E12: F 8298 MC | F12: Service radiator. perbaikan Bocor Ganti tutup atas + Ganti Air coolant | G12: Mahmudin | H12: 550000
A13: 9 | B13: 45838 | C13: FA322/IV/01 | D13: Honda Vario 125 CC | E13: F 5469 FJD | F13: Vanbelt, Roller, Oli Mesin, CVT | G13: Rispandi | H13: 384500
A14: 10 | B14: 45848 | C14: FA354/I/01 | D14: Printer Canon PIXMA G4770 All in One ADF WiFi FAX pengganti G4010 | E14: - | F14: Network | G14: Dimas | H14: 0
A15: 11 | B15: 45864 | C15: FA073/IV/01 | D15: Daihatsu Granmax | E15: F 8526 HS | F15: Busi, Oli Mesin, Filter Oli, Air Cleaner, Filter AC, Brake Fluid, Radiator Coolant + Flushing | G15: Rispandi | H15: 2990500
A16: 12 | B16: 45890 | C16: FA073/IV/01 | D16: Daihatsu Granmax | E16: F 8526 HS | F16: Ban | G16: Rispandi | H16: 2342500
A17: 13 | B17: 45913 | C17: FA073/IV/02 | D17: Daihatsu Granmax | E17: F 8526 HS | F17: AC | G17: Hendra | H17: 1500000
A18: 14 | B18: 45975 | C18: FA116/III/01 | D18: LENOVO IDEAPAD 3 14 i5 1035G1 8GB 256SSD W10 14.0FHD | F18: Maintenance & repasta | G18: Dimas | H18: 50000
A19: 15 | B19: 45978 | C19: FA116/III/01 | D19: LENOVO IDEAPAD 3 14 i5 1035G1 8GB 256SSD W10 14.0FHD | F19: Mainboard | G19: Dimas | H19: 0
A20: 16 | B20: 45973 | C20: FA398/III/01 | D20: Laptop Acer Nitro V 15 ANV15-51 i9-13900H RTX4060 512G 15.6”FHD 144Hz W11 OHS - Ram 64GB | F20: BIOS Password & Instal Ulang | G20: Dimas | H20: 0
A21: 17 | C21: FA066/III/01 | D21: ASUS TUF | FX506HC | I535B6TO11 |8GB 512SSD RTX3050 4GB GRY | F21: Instal Ulang Windows | G21: Dimas | H21: 0
A22: 18 | C22: FA318/III/01 | D22: HP PAVILION 14-DV2000TX I7-1255U 16GB 512GB SSD MX550 14" FHD IPS BACKLIT W11 OHS SILVER FINGERPRINT BAG 5CD242B8K2 | F22: Instal Ulang Windows | G22: Dimas | H22: 0
A23: 19 | B23: 45968 | C23: FA026/III/01 | D23: 3 MONITOR + KEYBOARD 2 + MOUSE 2 + ACC + KABEL VGA + KABEL USG EXT STD | F23: Repasta dan Intal Ulang Windows | G23: Dimas | H23: 75000
A24: 20 | B24: 45957 | C24: FA118/III/02 | D24: LENOVO IDEAPAD SLIM 3I I5-1235U 512GB SSD 8GB ABYSS BLUE | F24: Instal Ulang Windows | G24: Dimas | H24: 0
A25: 21 | B25: 45958 | C25: FA298/III/01 | D25: HP PAVILION 14-DV2000TX-I7-1255U 16GB 512 SSD MX550 | F25: Instal Ulang Windows | G25: Dimas | H25: 0
A26: 22
A27: 23
A28: 24
A29: 25
A30: 26
A31: 27
A32: 28
A33: 29
A34: 30
A35: 31
A36: 32
A37: 33
... A120: 116

Sheet Database
A2: Chendy Martika Jaya | B2: Chendy
A3: Joseline Olivia | B3: Joseline
A4: Stefanus Hodir | B4: Stefanus
A5: Shela Oktania | B5: Shela Oktania
A6: Silmi Khoiriyah | B6: Silmi
A7: Adi Kusumah | B7: Adi Kusumah
A8: Rafida Afnan | B8: Rafida
A9: Rispandi Mandala Putra | B9: Rispandi
A10: Fitria | B10: Fitria
A11: Corneleo Dimas Yulendra Wasisto | B11: Corneleo
A12: Harmoko | B12: Harmoko
A13: Melisa Aprilia | B13: Melisa
... A53: Carissa Christybella | B53: Carissa

Sheet Planning SO Asset 2024
A1: Planning SO Asset 2024
A3: PIC | C3: Activity | D3: Duration | E3: Start Date | F3: End Date | G3: Progress | H3: Notes
A4: Lead | B4: Support
A5: Dimas | B5: Rino, Kevin, Della | C5: Retagging All Asset | D5: 3 weeks | E5: 28/10/2024 | F5: 15/11/2024 | G5: Identified 263/269 Asset (BSD) Identified 136/142 Asset (Deltamas 1) Identified 19/21 Asset (Deltamas 2) Identified 16 assets not yet recorded | H5: 6 tidak teridentifikasi karena tidak ditemukan barangnya. (BSD) 4 odd | 3 lost (dari so tahun kemarin) | 123 active (tagged & identified) | 1 sold (2023) | 13 broken (deltamas 1) 203 Done | 9 Broken | 19 Missing | 15 not identified | 21 belum di tag | 3
A6: Arina | B6: Della | C6: Document Preparation | D6: 1 day | E6: 18/11/2024 | F6: 18/11/2024 | G6: Done (19/11/2024)
A7: Arina | B7: Della | C7: Team Briefing | D7: 1 day | E7: 18/11/2024 | F7: 18/11/2024 | G7: Done (20/11/2024)
A8: Dimas (BSD) Rino (Deltamas) | B8: Rispandi (BSD) Diki (Deltamas) | C8: Stock Opname Batch 1 | D8: 3 days | E8: 19/11/2024 | F8: 21/11/2024 | G8: Done
A9: Dimas (BSD) Rino (Deltamas) | B9: Arina, Della (BSD) Diki (Deltamas) | C9: Stock Opname Batch 2 | D9: 3 days | E9: 22/11/2024 | F9: 26/11/2024 | G9: Done
A10: Dimas (BSD) Rino (Deltamas) | B10: Rispandi, Agus RH (BSD) Wahyu QC (Deltamas) | C10: Stock Opname Batch 3 | D10: 3 days | E10: 27/11/2024 | F10: 29/11/2024 | G10: Done
A11: Della | B11: Rino | C11: Buffer Stock Opname | D11: 1 week | E11: 45334 | F11: 45455 | G11: In Progress | H11: Handover Inventory
A12: Arina | B12: Della | C12: Team Briefing | D12: 1 day | E12: 45547 | F12: 45547
A13: Arina | B13: Della | C13: Compile Stock Opname Report | D13: 2 days | E13: 45577 | F13: 45608
A14: Arina | B14: Della | C14: Report Stock Opname | D14: 1 day | E14: 45638 | F14: 45638
A15: Dimas (BSD) Rino (Deltamas) | B15: Arina, Della | C15: Reconciliation | D15: 3 days | E15: 13/12/2024 | F15: 17/12/2024
A16: Arina | B16: Della | C16: Meeting dg Purchasing & Finance | D16: 1 day | E16: 17/12/2024 | F16: 17/12/2024
A17: Arina | B17: Della | C17: Final Report Stock Opname | D17: 1 day | E17: 18/12/2024 | F17: 18/12/2024

Sheet Planning SO Asset 2025
A1: Planning SO Asset 2025
A3: PIC | C3: Activity | D3: Duration | E3: Start Date | F3: End Date | G3: Description
A4: Lead | B4: Support
A5: Dimas | B5: Arina, Della, Rino | C5: Development of Stock Opname Platform | D5: 10 Days | E5: 13/10/2025 | F5: 28/10/2025 | G5: Proses development platform asset management dengan fitur utama Stock Opname
A6: Dimas | B6: Arina, Della, Rino | C6: Data Optimalization on Stock Opname Platform | D6: 5 Days | E6: 20/10/2025 | F6: 28/10/2025 | G6: Proses optimalisasi data dan upload seluruh asset yang telah tercatat dari awal pembelian hingga asset yang dibeli pada September 2025
A7: Dimas | B7: Arina, Della, Rino, Rispandi, Andi | C7: Presentation of new Asset Management Platform | D7: 1 Day | E7: 29/10/2025 | F7: 29/10/2025
A8: Della | B8: Arina | C8: Team Briefing | D8: 1 Day | E8: 29/10/2025 | F8: 29/10/2025 | G8: Briefing informasi proses SO
A9: Della | B9: Rino, Dimas, Rispandi, Andi | C9: Tag Checking & Tagging New Asset | D9: 5 Days | E9: 45727 | F9: 45849 | G9: Proses checking setiap asset yang sudah diberi tag pada SO sebelumnya dan tagging asset baru 2025 sampai bulan September
A10: Dimas (BSD) Rino (Business Unit) | B10: Arina, Della, Rispandi, Andi | C10: Stock Opname | D10: 5 Days | E10: 45941 | F10: 14/11/2025
A11: Della | B11: Rino, Dimas, Rispandi, Andi | C11: Tagging New Asset | D11: 3 Days | E11: 45941 | F11: 46002 | G11: Proses tagging asset yang dibeli pada bulan Oktober 2025
A12: Della | B12: Arina, Dimas, Rispandi, Rino, Andi | C12: Maintenance Process for 'Broken' Assets | D12: 32 Days | E12: 45941 | F12: 46003
A13: Dimas (BSD) Rino (Business Unit) | B13: Arina, Della, Rispandi, Andi | C13: Buffer Stock Opname | D13: 5 Days | E13: 17/11/2025 | F13: 21/11/2025
A14: Della | B14: Arina, Rino | C14: Compile Stock Opname Report | D14: 5 Days | E14: 24/11/2025 | F14: 28/11/2025
A15: Della | B15: Rino, Dimas, Rispandi, Andi | C15: Tagging New Asset | D15: 3 Days | E15: 45669 | F15: 45728 | G15: Proses tagging asset yang dibeli pada bulan November 2025
A16: Della | B16: Arina, Dimas, Rispandi, Rino, Andi | C16: Finalization of Stock Opname | D16: 5 Days | E16: 45669 | F16: 45789
A17: Della | B17: Arina, Rino | C17: Report Stock Opname | D17: 3 Days | E17: 45728 | F17: 45789
A18: Della | B18: Arina | C18: Reconciliation | D18: 2 Days | E18: 45881 | F18: 46003
A19: Della | B19: Arina, Rino | C19: Final Report Stock Opname | D19: 1 Day | E19: 22/12/2025 | F19: 22/12/2025

Sheet Sheet10
B2: STOCK OPNAME TIMELINE
B5: PHASE | C5: DETAILS | H5: October | W5: November | AQ5: December | BI5: PIC
H7: 13 | I7: 14 | J7: 15 | K7: 16 | L7: 17 | M7: 20 | N7: 21 | O7: 22 | P7: 23 | Q7: 24 | R7: 27 | S7: 28 | T7: 29 | U7: 30 | V7: 31 | W7: 3 | X7: 4 | Y7: 5 | Z7: 6 | AA7: 7 | AB7: 10 | AC7: 11 | AD7: 12 | AE7: 13 | AF7: 14 | AG7: 17 | AH7: 18 | AI7: 19 | AJ7: 20 | AK7: 21 | AL7: 24 | AM7: 25 | AN7: 26 | AO7: 27 | AP7: 28 | AQ7: 1 | AR7: 2 | AS7: 3 | AT7: 4 | AU7: 5 | AV7: 8 | AW7: 9 | AX7: 10 | AY7: 11 | AZ7: 12 | BA7: 15 | BB7: 16 | BC7: 17 | BD7: 18 | BE7: 19 | BF7: 22 | BG7: 23 | BH7: 24
B8: 1 | C8: Development | F8: Development of Asset Management Platform | H8: Main Feature for Stock Opname | T8: Additional Feature | BH8: S O C O M P L E T E | BI8: Dimas
F9: Optimalization of new Asset Management Platform | M9: Main data for Stock Opname | T9: Additional Data and New Data of Fixed Asset | BI9: Dimas
F10: Presentation of new Asset Management Platform | BI10: Dimas
B11: 2 | C11: Administration | F11: Team Briefing | BI11: Della
F12: Administrative Fullfilment | H12: Pull data from Supply Chain & Crosscheck with Finance (Main Data) | W12: Pull data from Supply Chain & Crosscheck with Finance (Additional Data & New Assets) | BI12: Della
B13: 3 | C13: Stock Opname | F13: Tag Checking | BI13: Dimas, Rino
F14: Tagging New Asset | W14: New Asset from Jan to Sep | AB14: New Asset Oct | BI14: Dimas, Rino
F15: Stock Opname | AB15: SO Asset until Sep 25 | BI15: Dimas, Rino
F16: Buffer Stock Opname | AG16: SO Asset Oct 25 | BI16: Dimas, Rino
F17: Finalization Stock Opname | AQ17: Finalization for New Asset Nov 25 | BI17: Dimas, Rino
B18: 4 | C18: Maintenance | F18: Identification Process for 'Broken' Assets | AB18: Identification for Asset until Sep 25 | BI18: Arina, Della
F19: Assigning each Broken Assets to PIC | BI19: Arina, Della
F20: Maintenance Process for Broken Assets | BI20: Rino
B21: 5 | C21: Closing | F21: Report of Stock Opname Result | BI21: Della
F22: Reconciliation | BI22: Della
F23: Release Final Report of Stock Opname Result | BI23: Della

Sheet Analysis
A2: Total Assets | B2: =COUNTA('List of Assets'!F10:F1075) -> 538
A3: Site | C3: Status | E3: Cost
A4: BSD | B4: =countif('List of Assets'!L:L,A4) -> 307 | C4: Active | D4: =countif('List of Assets'!R:R,C4) -> 442 | E4: Finance | F4: =sum('List of Assets'!H:H) -> 8821439227 | G4: GA | H4: =sum('List of Assets'!I:I) -> 137215306
A5: Deltamas 1 | B5: =countif('List of Assets'!L:L,A5) -> 207 | C5: Lost/ Missing | D5: =countif('List of Assets'!R:R,C5) -> 19 | E5: Active | F5: =sumif('List of Assets'!R:R,E5,'List of Assets (Old Data)'!E:E) -> 8209886709 | G5: Active | H5: =sumif('List of Assets'!R:R,G5,'List of Assets'!I:I) -> 118916156
